Workbook

Sheet Autumn 2025
A1: key | B1: Course | C1: Title | D1: Quarter | E1: Year | F1: Day and Time | G1: Instructor | H1: Total Enrollment after Phase 1 | I1: Seats Available after Phase 1 | J1: Phase 1 Price | K1: Total Enrollment after Phase 2 | L1: Seats Available after Phase 2 | M1: Phase 2 Price | N1: Total Enrollment after Phase 1 New Students | O1: Seats Available after Phase 1 New Students | P1: Phase 1 New Students Price | Q1: Total Enrollment after Phase 2 New Students | R1: Seats Available after Phase 2 New Students | S1: Phase 2 New Students Price | T1: Total Enrollment after Phase 3 | U1: Seats Available after Phase 3 | V1: Phase 3 Price
A2: =LEFT('Autumn 2025'!B2,5) -> 42121 | B2: 42121-81 | C2: Merger & Acquisition Strategy | D2: Autumn | E2: 2025 | F2: Wednesday, 6:00 pm - 9:00 pm | G2: Morrissette, Stephen | H2: 70 | I2: CLO | J2: 15000 | K2: 70 | L2: CLO | M2: 15052 | N2: 70 | O2: CLO | P2: 0 | Q2: 70 | R2: CLO | S2: 0 | T2: 70 | U2: CLO | V2: 15040
A3: =LEFT('Autumn 2025'!B3,5) -> 34106 | B3: 34106-01 | C3: Commercializing Innovation: Tools to Research and Analyze Private Enterprises | D3: Autumn | E3: 2025 | F3: Thursday, 01:30 pm - 04:30 pm | G3: Meadow, Scott | H3: 55 | I3: CLO | J3: 9065 | K3: 55 | L3: CLO | M3: 13484 | N3: 55 | O3: CLO | P3: 0 | Q3: 55 | R3: CLO | S3: 0 | T3: 55 | U3: CLO | V3: 0
A4: =LEFT('Autumn 2025'!B4,5) -> 30000 | B4: 30000-01 | C4: Financial Accounting | D4: Autumn | E4: 2025 | F4: Monday, 01:30 pm - 04:30 pm | G4: Nikolaev, Valeri | H4: 3 | I4: 62 | J4: 0 | K4: 4 | L4: 61 | M4: 0 | N4: 65 | O4: CLO | P4: 0 | Q4: 65 | R4: CLO | S4: 777 | T4: 65 | U4: CLO | V4: 1844
A5: =LEFT('Autumn 2025'!B5,5) -> 38120 | B5: 38120-01 | C5: The Study of Behavioral Economics | D5: Autumn | E5: 2025 | F5: Wednesday, 08:30 am - 11:30 am | G5: Dean, Joshua | H5: 70 | I5: CLO | J5: 6012 | K5: 70 | L5: CLO | M5: 12007 | N5: 70 | O5: CLO | P5: 0 | Q5: 70 | R5: CLO | S5: 0 | T5: 70 | U5: CLO | V5: 0
A6: =LEFT('Autumn 2025'!B6,5) -> 30000 | B6: 30000-02 | C6: Financial Accounting | D6: Autumn | E6: 2025 | F6: Tuesday, 08:30 am - 11:30 am | G6: Nikolaev, Valeri | H6: 9 | I6: 56 | J6: 0 | K6: 9 | L6: 56 | M6: 0 | N6: 65 | O6: CLO | P6: 1201 | Q6: 65 | R6: CLO | S6: 0 | T6: 64 | U6: 1 | V6: 0
A7: =LEFT('Autumn 2025'!B7,5) -> 30000 | B7: 30000-03 | C7: Financial Accounting | D7: Autumn | E7: 2025 | F7: Tuesday, 01:30 pm - 04:30 pm | G7: Nikolaev, Valeri | H7: 8 | I7: 57 | J7: 0 | K7: 10 | L7: 55 | M7: 0 | N7: 65 | O7: CLO | P7: 300 | Q7: 65 | R7: CLO | S7: 1243 | T7: 65 | U7: CLO | V7: 2000
A8: =LEFT('Autumn 2025'!B8,5) -> 38103 | B8: 38103-01 | C8: Strategies and Processes of Negotiation | D8: Autumn | E8: 2025 | F8: Wednesday, 01:30 pm - 04:30 pm | G8: Kirgios, Erika | H8: 55 | I8: CLO | J8: 3250 | K8: 55 | L8: CLO | M8: 3000 | N8: 55 | O8: CLO | P8: 0 | Q8: 55 | R8: CLO | S8: 0 | T8: 55 | U8: CLO | V8: 5000
A9: =LEFT('Autumn 2025'!B9,5) -> 30000 | B9: 30000-04 | C9: Financial Accounting | D9: Autumn | E9: 2025 | F9: Friday, 08:30 am - 11:30 am | G9: Granja, Joao | H9: 1 | I9: 64 | J9: 0 | K9: 1 | L9: 64 | M9: 0 | N9: 53 | O9: 12 | P9: 0 | Q9: 54 | R9: 11 | S9: 0 | T9: 52 | U9: 13 | V9: 0
A10: =LEFT('Autumn 2025'!B10,5) -> 30000 | B10: 30000-05 | C10: Financial Accounting | D10: Autumn | E10: 2025 | F10: Friday, 01:30 pm - 04:30 pm | G10: Granja, Joao | H10: 5 | I10: 60 | J10: 0 | K10: 5 | L10: 60 | M10: 0 | N10: 39 | O10: 26 | P10: 0 | Q10: 47 | R10: 18 | S10: 0 | T10: 48 | U10: 17 | V10: 0
A11: =LEFT('Autumn 2025'!B11,5) -> 42001 | B11: 42001-01 | C11: Competitive Strategy | D11: Autumn | E11: 2025 | F11: Thursday, 01:30 pm - 04:30 pm | G11: Wollmann, Thomas | H11: 65 | I11: CLO | J11: 2100 | K11: 65 | L11: CLO | M11: 6035 | N11: 65 | O11: CLO | P11: 0 | Q11: 65 | R11: CLO | S11: 0 | T11: 65 | U11: CLO | V11: 5001
A12: =LEFT('Autumn 2025'!B12,5) -> 30000 | B12: 30000-06 | C12: Financial Accounting | D12: Autumn | E12: 2025 | F12: Wednesday, 08:30 am - 11:30 am | G12: Errico, Marco | H12: 6 | I12: 59 | J12: 0 | K12: 7 | L12: 58 | M12: 0 | N12: 65 | O12: CLO | P12: 88 | Q12: 65 | R12: CLO | S12: 1571 | T12: 65 | U12: CLO | V12: 375
A13: =LEFT('Autumn 2025'!B13,5) -> 42001 | B13: 42001-81 | C13: Competitive Strategy | D13: Autumn | E13: 2025 | F13: Thursday, 6:00 pm - 9:00 pm | G13: Wollmann, Thomas | H13: 65 | I13: CLO | J13: 1598 | K13: 65 | L13: CLO | M13: 4000 | N13: 65 | O13: CLO | P13: 0 | Q13: 65 | R13: CLO | S13: 0 | T13: 65 | U13: CLO | V13: 13505
A14: =LEFT('Autumn 2025'!B14,5) -> 30000 | B14: 30000-07 | C14: Financial Accounting | D14: Autumn | E14: 2025 | F14: Thursday, 08:30 am - 11:30 am | G14: Errico, Marco | H14: 1 | I14: 64 | J14: 0 | K14: 1 | L14: 64 | M14: 0 | N14: 35 | O14: 30 | P14: 0 | Q14: 65 | R14: CLO | S14: 10 | T14: 63 | U14: 2 | V14: 0
A15: =LEFT('Autumn 2025'!B15,5) -> 40101 | B15: 40101-01 | C15: Supply Chain Strategy and Practice | D15: Autumn | E15: 2025 | F15: Monday, 08:30 am - 11:30 am | G15: DeHoratius, Nicole | H15: 65 | I15: CLO | J15: 909 | K15: 65 | L15: CLO | M15: 1988 | N15: 65 | O15: CLO | P15: 0 | Q15: 65 | R15: CLO | S15: 0 | T15: 65 | U15: CLO | V15: 2543
A16: =LEFT('Autumn 2025'!B16,5) -> 30121 | B16: 30121-01 | C16: Accounting for Entrepreneurship: From Start-Up through IPO | D16: Autumn | E16: 2025 | F16: Tuesday, 08:30 am - 11:30 am | G16: Weiss, Ira | H16: 65 | I16: CLO | J16: 500 | K16: 65 | L16: CLO | M16: 4091 | N16: 65 | O16: CLO | P16: 0 | Q16: 65 | R16: CLO | S16: 0 | T16: 65 | U16: CLO | V16: 1500
A17: =LEFT('Autumn 2025'!B17,5) -> 36110 | B17: 36110-81 | C17: Application Development | D17: Autumn | E17: 2025 | F17: Wednesday, 6:00 pm - 9:00 pm | G17: Betina, Raghu | H17: 30 | I17: CLO | J17: 300 | K17: 27 | L17: 3 | M17: 0 | N17: 28 | O17: 2 | P17: 0 | Q17: 29 | R17: 1 | S17: 0 | T17: 30 | U17: CLO | V17: 12000
A18: =LEFT('Autumn 2025'!B18,5) -> 34305 | B18: 34305-01 | C18: Private Equity Transactions | D18: Autumn | E18: 2025 | F18: Thursday, 3:00 pm - 6:00 pm | G18: Ritchie, Stephen | H18: 30 | I18: CLO | J18: 259 | K18: 30 | L18: CLO | M18: 1000 | N18: 30 | O18: CLO | P18: 0 | Q18: 30 | R18: CLO | S18: 0 | T18: 30 | U18: CLO | V18: 0
A19: =LEFT('Autumn 2025'!B19,5) -> 30000 | B19: 30000-81 | C19: Financial Accounting | D19: Autumn | E19: 2025 | F19: Monday, 6:00 pm - 9:00 pm | G19: Nikolaev, Valeri | H19: 12 | I19: 53 | J19: 0 | K19: 12 | L19: 53 | M19: 0 | N19: 30 | O19: 35 | P19: 0 | Q19: 30 | R19: 35 | S19: 0 | T19: 33 | U19: 32 | V19: 0
A20: =LEFT('Autumn 2025'!B20,5) -> 34111 | B20: 34111-01 | C20: Entrepreneurial Selling | D20: Autumn | E20: 2025 | F20: Tuesday, 01:30 pm - 04:30 pm | G20: Alter, Michael | H20: 65 | I20: CLO | J20: 202 | K20: 65 | L20: CLO | M20: 5000 | N20: 65 | O20: CLO | P20: 0 | Q20: 65 | R20: CLO | S20: 0 | T20: 65 | U20: CLO | V20: 6747
A21: =LEFT('Autumn 2025'!B21,5) -> 35222 | B21: 35222-01 | C21: Corporate Governance and Activism - Board and Director Roles in Critical Decisions | D21: Autumn | E21: 2025 | F21: Thursday, 1:30 pm - 4:30 pm | G21: Adrianopoli, Carlin; Hessler, Stephen; Schriesheim, Robert | H21: 60 | I21: CLO | J21: 193 | K21: 60 | L21: CLO | M21: 15000 | N21: 60 | O21: CLO | P21: 0 | Q21: 60 | R21: CLO | S21: 0 | T21: 65 | U21: CLO | V21: 2805
A22: =LEFT('Autumn 2025'!B22,5) -> 30000 | B22: 30000-85 | C22: Financial Accounting | D22: Autumn | E22: 2025 | F22: Saturday, 1:30 pm - 4:30 pm | G22: Errico, Marco | H22: 9 | I22: 56 | J22: 0 | K22: 8 | L22: 57 | M22: 0 | N22: 29 | O22: 36 | P22: 0 | Q22: 28 | R22: 37 | S22: 0 | T22: 36 | U22: 29 | V22: 0
A23: =LEFT('Autumn 2025'!B23,5) -> 30130 | B23: 30130-01 | C23: Financial Statement Analysis | D23: Autumn | E23: 2025 | F23: Wednesday, 01:30 pm - 04:30 pm | G23: Minnis, Michael | H23: 65 | I23: CLO | J23: 3238 | K23: 65 | L23: CLO | M23: 4207 | N23: 65 | O23: CLO | P23: 0 | Q23: 65 | R23: CLO | S23: 0 | T23: 65 | U23: CLO | V23: 3000
A24: =LEFT('Autumn 2025'!B24,5) -> 30130 | B24: 30130-81 | C24: Financial Statement Analysis | D24: Autumn | E24: 2025 | F24: Wednesday, 6:00 pm - 9:00 pm | G24: Minnis, Michael | H24: 25 | I24: 40 | J24: 0 | K24: 24 | L24: 41 | M24: 0 | N24: 29 | O24: 36 | P24: 0 | Q24: 29 | R24: 36 | S24: 0 | T24: 65 | U24: CLO | V24: 1
A25: =LEFT('Autumn 2025'!B25,5) -> 33001 | B25: 33001-01 | C25: Microeconomics | D25: Autumn | E25: 2025 | F25: Monday, 08:30 am - 11:30 am | G25: Hornbeck, Richard | H25: 4 | I25: 61 | J25: 0 | K25: 3 | L25: 62 | M25: 0 | N25: 65 | O25: CLO | P25: 0 | Q25: 65 | R25: CLO | S25: 1031 | T25: 65 | U25: CLO | V25: 0
A26: =LEFT('Autumn 2025'!B26,5) -> 33001 | B26: 33001-02 | C26: Microeconomics | D26: Autumn | E26: 2025 | F26: Monday, 01:30 pm - 04:30 pm | G26: Hornbeck, Richard | H26: 3 | I26: 62 | J26: 0 | K26: 5 | L26: 60 | M26: 0 | N26: 62 | O26: 3 | P26: 0 | Q26: 65 | R26: CLO | S26: 1 | T26: 65 | U26: CLO | V26: 0
A27: =LEFT('Autumn 2025'!B27,5) -> 33001 | B27: 33001-03 | C27: Microeconomics | D27: Autumn | E27: 2025 | F27: Thursday, 08:30 am - 11:30 am | G27: Dizon-Ross, Rebecca | H27: 10 | I27: 55 | J27: 0 | K27: 11 | L27: 54 | M27: 0 | N27: 65 | O27: CLO | P27: 1024 | Q27: 65 | R27: CLO | S27: 3435 | T27: 65 | U27: CLO | V27: 751
A28: =LEFT('Autumn 2025'!B28,5) -> 33001 | B28: 33001-04 | C28: Microeconomics | D28: Autumn | E28: 2025 | F28: Thursday, 01:30 pm - 04:30 pm | G28: Dizon-Ross, Rebecca | H28: 10 | I28: 55 | J28: 0 | K28: 13 | L28: 52 | M28: 0 | N28: 65 | O28: CLO | P28: 1117 | Q28: 65 | R28: CLO | S28: 2137 | T28: 65 | U28: CLO | V28: 0
A29: =LEFT('Autumn 2025'!B29,5) -> 33001 | B29: 33001-05 | C29: Microeconomics | D29: Autumn | E29: 2025 | F29: Friday, 08:30 am - 11:30 am | G29: Dizon-Ross, Rebecca | H29: 2 | I29: 63 | J29: 0 | K29: 2 | L29: 63 | M29: 0 | N29: 62 | O29: 3 | P29: 0 | Q29: 65 | R29: CLO | S29: 0 | T29: 65 | U29: CLO | V29: 0
A30: =LEFT('Autumn 2025'!B30,5) -> 33001 | B30: 33001-06 | C30: Microeconomics | D30: Autumn | E30: 2025 | F30: Tuesday, 01:30 pm - 04:30 pm | G30: Gibbs, Michael | H30: 27 | I30: 38 | J30: 0 | K30: 27 | L30: 38 | M30: 0 | N30: 65 | O30: CLO | P30: 2401 | Q30: 65 | R30: CLO | S30: 2209 | T30: 65 | U30: CLO | V30: 0
A31: =LEFT('Autumn 2025'!B31,5) -> 30116 | B31: 30116-01 | C31: Accounting and Financial Analysis | D31: Autumn | E31: 2025 | F31: Tuesday, 08:30 am - 11:30 am | G31: Christensen, Hans | H31: 5 | I31: 60 | J31: 0 | K31: 6 | L31: 59 | M31: 0 | N31: 65 | O31: CLO | P31: 508 | Q31: 63 | R31: 2 | S31: 0 | T31: 65 | U31: CLO | V31: 10
A32: =LEFT('Autumn 2025'!B32,5) -> 30116 | B32: 30116-02 | C32: Accounting and Financial Analysis | D32: Autumn | E32: 2025 | F32: Tuesday, 01:30 pm - 04:30 pm | G32: Christensen, Hans | H32: 5 | I32: 60 | J32: 0 | K32: 7 | L32: 58 | M32: 0 | N32: 49 | O32: 16 | P32: 0 | Q32: 52 | R32: 13 | S32: 0 | T32: 49 | U32: 16 | V32: 0
A33: =LEFT('Autumn 2025'!B33,5) -> 30118 | B33: 30118-81 | C33: Taxes and Business Strategy | D33: Autumn | E33: 2025 | F33: Monday, 6:00 pm - 9:00 pm | G33: Erickson, Merle | H33: 51 | I33: 14 | J33: 0 | K33: 52 | L33: 13 | M33: 0 | N33: 53 | O33: 12 | P33: 0 | Q33: 53 | R33: 12 | S33: 0 | T33: 65 | U33: CLO | V33: 3000
A34: =LEFT('Autumn 2025'!B34,5) -> 30121 | B34: 30121-02 | C34: Accounting for Entrepreneurship: From Start-Up through IPO | D34: Autumn | E34: 2025 | F34: Monday, 01:30 pm - 04:30 pm | G34: Weiss, Ira | H34: 11 | I34: 54 | J34: 0 | K34: 11 | L34: 54 | M34: 0 | N34: 21 | O34: 44 | P34: 0 | Q34: 21 | R34: 44 | S34: 0 | T34: 41 | U34: 24 | V34: 0
A35: =LEFT('Autumn 2025'!B35,5) -> 30121 | B35: 30121-81 | C35: Accounting for Entrepreneurship: From Start-Up through IPO | D35: Autumn | E35: 2025 | F35: Monday, 6:00 pm - 9:00 pm | G35: Weiss, Ira | H35: 33 | I35: 32 | J35: 0 | K35: 33 | L35: 32 | M35: 0 | N35: 33 | O35: 32 | P35: 0 | Q35: 33 | R35: 32 | S35: 0 | T35: 41 | U35: 24 | V35: 0
A36: =LEFT('Autumn 2025'!B36,5) -> 30121 | B36: 30121-85 | C36: Accounting for Entrepreneurship: From Start-Up through IPO | D36: Autumn | E36: 2025 | F36: Saturday, 1:30 pm - 4:30 pm | G36: Weiss, Ira | H36: 31 | I36: 34 | J36: 0 | K36: 31 | L36: 34 | M36: 0 | N36: 35 | O36: 30 | P36: 0 | Q36: 35 | R36: 30 | S36: 0 | T36: 38 | U36: 27 | V36: 0
A37: =LEFT('Autumn 2025'!B37,5) -> 33001 | B37: 33001-07 | C37: Microeconomics | D37: Autumn | E37: 2025 | F37: Tuesday, 08:30 am - 11:30 am | G37: McClellan, Andrew | H37: 3 | I37: 62 | J37: 0 | K37: 2 | L37: 63 | M37: 0 | N37: 55 | O37: 10 | P37: 0 | Q37: 65 | R37: CLO | S37: 2717 | T37: 65 | U37: CLO | V37: 4023
A38: =LEFT('Autumn 2025'!B38,5) -> 30131 | B38: 30131-01 | C38: Advanced Financial Analysis and Valuation for Global Firms | D38: Autumn | E38: 2025 | F38: Monday, 01:30 pm - 04:30 pm | G38: McClure, Charles | H38: 25 | I38: 40 | J38: 0 | K38: 25 | L38: 40 | M38: 0 | N38: 60 | O38: 5 | P38: 0 | Q38: 62 | R38: 3 | S38: 0 | T38: 62 | U38: 3 | V38: 0
A39: =LEFT('Autumn 2025'!B39,5) -> 30131 | B39: 30131-02 | C39: Advanced Financial Analysis and Valuation for Global Firms | D39: Autumn | E39: 2025 | F39: Monday, 05:00 pm - 08:00 pm | G39: McClure, Charles | H39: 8 | I39: 57 | J39: 0 | K39: 8 | L39: 57 | M39: 0 | N39: 10 | O39: 55 | P39: 0 | Q39: 12 | R39: 53 | S39: 0 | T39: 12 | U39: 53 | V39: 0
A40: =LEFT('Autumn 2025'!B40,5) -> 30131 | B40: 30131-03 | C40: Advanced Financial Analysis and Valuation for Global Firms | D40: Autumn | E40: 2025 | F40: Monday, 08:30 am - 11:30 am | G40: McClure, Charles | H40: 30 | I40: 35 | J40: 0 | K40: 33 | L40: 32 | M40: 0 | N40: 61 | O40: 4 | P40: 0 | Q40: 65 | R40: CLO | S40: 1000 | T40: 65 | U40: CLO | V40: 1
...
